import pytest
from unittest.mock import AsyncMock, patch
from app.services.tracking import (
    handle_acknowledgment,
    process_location_update,
    retrieve_nearby_drivers,
    update_driver_location,
    WebSocketManager
)

@pytest.mark.asyncio
async def test_handle_valid_acknowledgment():
    acknowledgment_data = {"booking_id": "123", "status": "confirmed"}
    result = await handle_acknowledgment(acknowledgment_data)
    assert result is True

@pytest.mark.asyncio
async def test_acknowledgment_missing_booking_id():
    acknowledgment_data = {"status": "confirmed"}
    with pytest.raises(KeyError):
        await handle_acknowledgment(acknowledgment_data)

@pytest.mark.asyncio
async def test_acknowledgment_invalid_status():
    acknowledgment_data = {"booking_id": "123", "status": "invalid_status"}
    with pytest.raises(ValueError):
        await handle_acknowledgment(acknowledgment_data)

@pytest.mark.asyncio
async def test_process_valid_location_update():
    location_data = {"latitude": 37.7749, "longitude": -122.4194}
    result = await process_location_update(location_data)
    assert result is True

@pytest.mark.asyncio
async def test_location_update_missing_fields():
    location_data = {"latitude": 37.7749}
    with pytest.raises(KeyError):
        await process_location_update(location_data)

@pytest.mark.asyncio
async def test_malformed_location_data():
    location_data = {"lat": 37.7749, "long": -122.4194}  # Incorrect keys
    with pytest.raises(ValueError):
        await process_location_update(location_data)

@pytest.mark.asyncio
async def test_retrieve_nearby_drivers_available():
    with patch('app.services.tracking.find_nearby_drivers', return_value=[{"driver_id": "1"}]):
        drivers = await retrieve_nearby_drivers(37.7749, -122.4194)
        assert len(drivers) > 0

@pytest.mark.asyncio
async def test_retrieve_nearby_drivers_none_available():
    with patch('app.services.tracking.find_nearby_drivers', return_value=[]):
        drivers = await retrieve_nearby_drivers(37.7749, -122.4194)
        assert len(drivers) == 0

@pytest.mark.asyncio
async def test_driver_location_update_success():
    driver_data = {"driver_id": "1", "latitude": 37.7749, "longitude": -122.4194}
    with patch('app.services.tracking.publish_to_kafka', return_value=True):
        result = await update_driver_location(driver_data)
        assert result is True

@pytest.mark.asyncio
async def test_driver_location_update_kafka_failure():
    driver_data = {"driver_id": "1", "latitude": 37.7749, "longitude": -122.4194}
    with patch('app.services.tracking.publish_to_kafka', side_effect=Exception("Kafka error")):
        with pytest.raises(Exception):
            await update_driver_location(driver_data)

@pytest.mark.asyncio
async def test_websocket_connection_handling():
    websocket = AsyncMock()
    token = "valid_token"
    with patch('app.services.tracking.authenticate_websocket', return_value=True):
        manager = WebSocketManager()
        await manager.connect(websocket, token)
        assert websocket in manager.active_connections

@pytest.mark.asyncio
async def test_unauthorized_websocket_connection():
    websocket = AsyncMock()
    token = "invalid_token"
    with patch('app.services.tracking.authenticate_websocket', return_value=False):
        manager = WebSocketManager()
        with pytest.raises(ValueError):
            await manager.connect(websocket, token)

@pytest.mark.asyncio
async def test_graceful_websocket_disconnection():
    websocket = AsyncMock()
    manager = WebSocketManager()
    manager.active_connections.add(websocket)
    await manager.disconnect(websocket)
    assert websocket not in manager.active_connections